<?xml version="1.0" encoding="utf-8"?>
<!-- This URDF was automatically created by SolidWorks to URDF Exporter! Originally created by Stephen Brawner (brawner@gmail.com) 
     Commit Version: 1.6.0-1-g15f4949  Build Version: 1.6.7594.29634
     For more information, please see http://wiki.ros.org/sw_urdf_exporter -->
<robot
  name="optimus">
  
  <link 
    name="base_link">
  </link>

  <joint name="base_link_joint" type="fixed">
    <origin xyz="0 0 0" rpy="0 0 0" />
    <parent link="base_link"/>
    <child link="chassis_link" />
  </joint>

  <link
    name="chassis_link">
    <inertial>
      <origin
        xyz="0.0459672296914867 -6.86455399960119E-18 0.159649135028823"
        rpy="0 0 0" />
      <mass
        value="27.6398700040798" />
      <inertia
        ixx="0.443915191264158"
        ixy="-4.98377702946499E-18"
        ixz="0.0794061625736433"
        iyy="2.52334514759194"
        iyz="-4.33942541392612E-18"
        izz="2.9153112034191" />
    </inertial>
    <visual>
      <origin
        xyz="0 0 0"
        rpy="0 0 0" />
      <geometry>
        <mesh
          filename="package://optimus/meshes/chassis_link.STL" />
      </geometry>
      <material
        name="Gazebo/DarkGrey">
        <color
          rgba="0.792156862745098 0.819607843137255 0.933333333333333 1" />
      </material>
    </visual>
    <collision>
      <origin
        xyz="0 0 0"
        rpy="0 0 0" />
      <geometry>
        <mesh
          filename="package://optimus/meshes/chassis_link.STL" />
      </geometry>
    </collision>
  </link>
  
  <link
    name="FR_mid_connector_link">
    <inertial>
      <origin
        xyz="-6.656468502797E-05 -0.025165065848375 -0.006584934151625"
        rpy="0 0 0" />
      <mass
        value="0.111218290944422" />
      <inertia
        ixx="4.72825951749508E-05"
        ixy="-4.70682175763755E-22"
        ixz="6.95276245951139E-22"
        iyy="4.15796957339012E-05"
        iyz="-8.78847811785193E-06"
        izz="4.15796957339012E-05" />
    </inertial>
    <visual>
      <origin
        xyz="0 0 0"
        rpy="0 0 0" />
      <geometry>
        <mesh
          filename="package://optimus/meshes/FR_mid_connector_link.STL" />
      </geometry>
      <material
        name="">
        <color
          rgba="0.792156862745098 0.819607843137255 0.933333333333333 1" />
      </material>
    </visual>
    <collision>
      <origin
        xyz="0 0 0"
        rpy="0 0 0" />
      <geometry>
        <mesh
          filename="package://optimus/meshes/FR_mid_connector_link.STL" />
      </geometry>
    </collision>
  </link>
  
  <joint
    name="FR_mid_connector_joint"
    type="fixed">
    <origin
      xyz="0.25407 -0.127 0.16555"
      rpy="0 0 0" />
    <parent
      link="chassis_link" />
    <child
      link="FR_mid_connector_link" />
    <axis
      xyz="0 0 0" />
  </joint>
  
  <link
    name="FR_wheel_connector_link">
    <inertial>
      <origin
        xyz="0 -0.00803311644068047 -0.025165065848375"
        rpy="0 0 0" />
      <mass
        value="0.111218290944422" />
      <inertia
        ixx="4.72825951749508E-05"
        ixy="-6.78684332773796E-22"
        ixz="-1.62847215507893E-22"
        iyy="4.15796957339012E-05"
        iyz="-8.78847811785193E-06"
        izz="4.15796957339012E-05" />
    </inertial>
    <visual>
      <origin
        xyz="0 0 0"
        rpy="0 0 0" />
      <geometry>
        <mesh
          filename="package://optimus/meshes/FR_wheel_connector_link.STL" />
      </geometry>
      <material
        name="">
        <color
          rgba="0.792156862745098 0.819607843137255 0.933333333333333 1" />
      </material>
    </visual>
    <collision>
      <origin
        xyz="0 0 0"
        rpy="0 0 0" />
      <geometry>
        <mesh
          filename="package://optimus/meshes/FR_wheel_connector_link.STL" />
      </geometry>
    </collision>
  </link>
  
  <joint
    name="FR_wheel_connector_joint"
    type="revolute">
    <origin
      xyz="-6.6565E-05 -0.033198 -0.03175"
      rpy="0 0 0" />
    <parent
      link="FR_mid_connector_link" />
    <child
      link="FR_wheel_connector_link" />
    <axis
      xyz="0 0 1" />
    <limit
      lower="-0.6"
      upper="0.6"
      effort="10.0"
      velocity="10.0" />
    <!-- <dynamics
      friction="0.1"
      damping="0.1" /> -->
  </joint>

  <transmission name="FR_wheel_connector_trans">
    <type>transmission_interface/SimpleTransmission</type>
    <joint name="FR_wheel_connector_joint">
      <hardwareInterface>hardware_interface/PositionJointInterface</hardwareInterface>
    </joint>
    <actuator name="FR_wheel_connector_actuator">
      <mechanicalReduction>1</mechanicalReduction>
      <hardwareInterface>hardware_interface/PositionJointInterface</hardwareInterface>
    </actuator>
  </transmission>
  
  <link
    name="FR_wheel_link">
    <inertial>
      <origin
        xyz="-6.65646850267487E-05 -0.0381000000000005 -0.00144818228905787"
        rpy="0 0 0" />
      <mass
        value="1.37478617203279" />
      <inertia
        ixx="0.00468685600007827"
        ixy="-1.44994942300076E-18"
        ixz="-7.59946436264757E-19"
        iyy="0.00804327643003352"
        iyz="-3.6201576967064E-18"
        izz="0.00468685600007826" />
    </inertial>
    <visual>
      <origin
        xyz="0 0 0"
        rpy="0 0 0" />
      <geometry>
        <mesh
          filename="package://optimus/meshes/FR_wheel_link.STL" />
      </geometry>
      <material
        name="">
        <color
          rgba="0.792156862745098 0.819607843137255 0.933333333333333 1" />
      </material>
    </visual>
    <collision>
      <origin
        xyz="0 0 0"
        rpy="0 0 0" />
      <geometry>
        <mesh
          filename="package://optimus/meshes/FR_wheel_link.STL" />
      </geometry>
    </collision>
  </link>
  
  <joint
    name="FR_wheel_joint"
    type="continuous">
    <origin
      xyz="6.656468502797E-05 -0.0331981822890555 -0.03175"
      rpy="0 0 0" />
    <parent
      link="FR_wheel_connector_link" />
    <child
      link="FR_wheel_link" />
    <axis
      xyz="0 1 0" />
  </joint>

  <transmission name="FR_wheel_trans">
    <type>transmission_interface/SimpleTransmission</type>
    <joint name="FR_wheel_joint">
      <hardwareInterface>hardware_interface/VelocityJointInterface</hardwareInterface>
    </joint>
    <actuator name="FR_wheel_actuator">
      <mechanicalReduction>1</mechanicalReduction>
      <hardwareInterface>hardware_interface/VelocityJointInterface</hardwareInterface>
    </actuator>
  </transmission>
  
  <link
    name="FL_mid_connector_link">
    <inertial>
      <origin
        xyz="0 0.025165065848375 -0.00803311644068052"
        rpy="0 0 0" />
      <mass
        value="0.111218290944422" />
      <inertia
        ixx="4.72825951749508E-05"
        ixy="-4.78762785695293E-22"
        ixz="-2.46370706228464E-21"
        iyy="4.15796957339013E-05"
        iyz="8.78847811785194E-06"
        izz="4.15796957339012E-05" />
    </inertial>
    <visual>
      <origin
        xyz="0 0 0"
        rpy="0 0 0" />
      <geometry>
        <mesh
          filename="package://optimus/meshes/FL_mid_connector_link.STL" />
      </geometry>
      <material
        name="">
        <color
          rgba="0.792156862745098 0.819607843137255 0.933333333333333 1" />
      </material>
    </visual>
    <collision>
      <origin
        xyz="0 0 0"
        rpy="0 0 0" />
      <geometry>
        <mesh
          filename="package://optimus/meshes/FL_mid_connector_link.STL" />
      </geometry>
    </collision>
  </link>
  
  <joint
    name="FL_mid_connector_joint"
    type="fixed">
    <origin
      xyz="0.254 0.127 0.167"
      rpy="0 0 0" />
    <parent
      link="chassis_link" />
    <child
      link="FL_mid_connector_link" />
    <axis
      xyz="0 0 0" />
  </joint>
  
  <link
    name="FL_wheel_connector_link">
    <inertial>
      <origin
        xyz="-6.656468502797E-05 0.00948129872973585 -0.025165065848375"
        rpy="0 0 0" />
      <mass
        value="0.111218290944422" />
      <inertia
        ixx="4.72825951749508E-05"
        ixy="1.429851898539E-21"
        ixz="4.86705630527466E-22"
        iyy="4.15796957339013E-05"
        iyz="8.78847811785193E-06"
        izz="4.15796957339012E-05" />
    </inertial>
    <visual>
      <origin
        xyz="0 0 0"
        rpy="0 0 0" />
      <geometry>
        <mesh
          filename="package://optimus/meshes/FL_wheel_connector_link.STL" />
      </geometry>
      <material
        name="">
        <color
          rgba="0.792156862745098 0.819607843137255 0.933333333333333 1" />
      </material>
    </visual>
    <collision>
      <origin
        xyz="0 0 0"
        rpy="0 0 0" />
      <geometry>
        <mesh
          filename="package://optimus/meshes/FL_wheel_connector_link.STL" />
      </geometry>
    </collision>
  </link>
  
  <joint
    name="FL_wheel_connector_joint"
    type="revolute">
    <origin
      xyz="6.6565E-05 0.03175 -0.033198"
      rpy="0 0 0" />
    <parent
      link="FL_mid_connector_link" />
    <child
      link="FL_wheel_connector_link" />
    <axis
      xyz="0 0 1" />
    <limit
      lower="-0.6"
      upper="0.6"
      effort="10.0"
      velocity="10.0" />
    <!-- <dynamics
      friction="0.1"
      damping="0.1" /> -->
  </joint>

  <transmission name="FL_wheel_connector_trans">
    <type>transmission_interface/SimpleTransmission</type>
    <joint name="FL_wheel_connector_joint">
      <hardwareInterface>hardware_interface/PositionJointInterface</hardwareInterface>
    </joint>
    <actuator name="FL_wheel_connector_actuator">
      <mechanicalReduction>1</mechanicalReduction>
      <hardwareInterface>hardware_interface/PositionJointInterface</hardwareInterface>
    </actuator>
  </transmission>
  
  <link
    name="FL_wheel_link">
    <inertial>
      <origin
        xyz="-1.38777878078145E-15 0.0381000000000001 2.0122792321331E-15"
        rpy="0 0 0" />
      <mass
        value="1.37478617203279" />
      <inertia
        ixx="0.00468685600007827"
        ixy="-2.15687431241997E-18"
        ixz="-2.05140791913338E-19"
        iyy="0.00804327643003352"
        iyz="-3.30768332749193E-19"
        izz="0.00468685600007827" />
    </inertial>
    <visual>
      <origin
        xyz="0 0 0"
        rpy="0 0 0" />
      <geometry>
        <mesh
          filename="package://optimus/meshes/FL_wheel_link.STL" />
      </geometry>
      <material
        name="">
        <color
          rgba="0.792156862745098 0.819607843137255 0.933333333333333 1" />
      </material>
    </visual>
    <collision>
      <origin
        xyz="0 0 0"
        rpy="0 0 0" />
      <geometry>
        <mesh
          filename="package://optimus/meshes/FL_wheel_link.STL" />
      </geometry>
    </collision>
  </link>
  
  <joint
    name="FL_wheel_joint"
    type="continuous">
    <origin
      xyz="-6.6565E-05 0.034646 -0.033198"
      rpy="0 0 0" />
    <parent
      link="FL_wheel_connector_link" />
    <child
      link="FL_wheel_link" />
    <axis
      xyz="0 1 0" />
  </joint>

  <transmission name="FL_wheel_trans">
    <type>transmission_interface/SimpleTransmission</type>
    <joint name="FL_wheel_joint">
      <hardwareInterface>hardware_interface/VelocityJointInterface</hardwareInterface>
    </joint>
    <actuator name="FL_wheel_actuator">
      <mechanicalReduction>1</mechanicalReduction>
      <hardwareInterface>hardware_interface/VelocityJointInterface</hardwareInterface>
    </actuator>
  </transmission>
  
  <link
    name="RR_mid_connector_link">
    <inertial>
      <origin
        xyz="-6.656468502797E-05 -0.025165065848375 -0.00658493415162501"
        rpy="0 0 0" />
      <mass
        value="0.111218290944422" />
      <inertia
        ixx="4.72825951749508E-05"
        ixy="-1.20292624299967E-21"
        ixz="-2.62828261983991E-21"
        iyy="4.15796957339012E-05"
        iyz="-8.78847811785193E-06"
        izz="4.15796957339012E-05" />
    </inertial>
    <visual>
      <origin
        xyz="0 0 0"
        rpy="0 0 0" />
      <geometry>
        <mesh
          filename="package://optimus/meshes/RR_mid_connector_link.STL" />
      </geometry>
      <material
        name="">
        <color
          rgba="0.792156862745098 0.819607843137255 0.933333333333333 1" />
      </material>
    </visual>
    <collision>
      <origin
        xyz="0 0 0"
        rpy="0 0 0" />
      <geometry>
        <mesh
          filename="package://optimus/meshes/RR_mid_connector_link.STL" />
      </geometry>
    </collision>
  </link>
  
  <joint
    name="RR_mid_connector_joint"
    type="fixed">
    <origin
      xyz="-0.25395 -0.127 0.16555"
      rpy="0 0 0" />
    <parent
      link="chassis_link" />
    <child
      link="RR_mid_connector_link" />
    <axis
      xyz="0 0 0" />
  </joint>
  
  <link
    name="RR_wheel_connector_link">
    <inertial>
      <origin
        xyz="-1.66533453693773E-16 -0.00803311644068039 -0.025165065848375"
        rpy="0 0 0" />
      <mass
        value="0.111218290944422" />
      <inertia
        ixx="4.72825951749508E-05"
        ixy="-2.88105234958646E-21"
        ixz="3.86153412936947E-21"
        iyy="4.15796957339012E-05"
        iyz="-8.78847811785193E-06"
        izz="4.15796957339012E-05" />
    </inertial>
    <visual>
      <origin
        xyz="0 0 0"
        rpy="0 0 0" />
      <geometry>
        <mesh
          filename="package://optimus/meshes/RR_wheel_connector_link.STL" />
      </geometry>
      <material
        name="">
        <color
          rgba="0.792156862745098 0.819607843137255 0.933333333333333 1" />
      </material>
    </visual>
    <collision>
      <origin
        xyz="0 0 0"
        rpy="0 0 0" />
      <geometry>
        <mesh
          filename="package://optimus/meshes/RR_wheel_connector_link.STL" />
      </geometry>
    </collision>
  </link>
  
  <joint
    name="RR_wheel_connector_joint"
    type="fixed">
    <origin
      xyz="-6.6565E-05 -0.033198 -0.03175"
      rpy="0 0 0" />
    <parent
      link="RR_mid_connector_link" />
    <child
      link="RR_wheel_connector_link" />
    <axis
      xyz="0 0 0" />
  </joint>
  
  <link
    name="RR_wheel_link">
    <inertial>
      <origin
        xyz="-6.65646850281365E-05 -0.0381000000000002 -0.00144818228905499"
        rpy="0 0 0" />
      <mass
        value="1.37478617203279" />
      <inertia
        ixx="0.00468685600007826"
        ixy="-6.65290787924846E-19"
        ixz="3.27149932264726E-18"
        iyy="0.00804327643003351"
        iyz="2.61538024465355E-18"
        izz="0.00468685600007826" />
    </inertial>
    <visual>
      <origin
        xyz="0 0 0"
        rpy="0 0 0" />
      <geometry>
        <mesh
          filename="package://optimus/meshes/RR_wheel_link.STL" />
      </geometry>
      <material
        name="">
        <color
          rgba="0.792156862745098 0.819607843137255 0.933333333333333 1" />
      </material>
    </visual>
    <collision>
      <origin
        xyz="0 0 0"
        rpy="0 0 0" />
      <geometry>
        <mesh
          filename="package://optimus/meshes/RR_wheel_link.STL" />
      </geometry>
    </collision>
  </link>
  
  <joint
    name="RR_wheel_joint"
    type="continuous">
    <origin
      xyz="6.65646850278034E-05 -0.0331981822890554 -0.03175"
      rpy="0 0 0" />
    <parent
      link="RR_wheel_connector_link" />
    <child
      link="RR_wheel_link" />
    <axis
      xyz="0 1 0" />
  </joint>

  <transmission name="RR_wheel_trans">
    <type>transmission_interface/SimpleTransmission</type>
    <joint name="RR_wheel_joint">
      <hardwareInterface>hardware_interface/VelocityJointInterface</hardwareInterface>
    </joint>
    <actuator name="RR_wheel_actuator">
      <mechanicalReduction>1</mechanicalReduction>
      <hardwareInterface>hardware_interface/VelocityJointInterface</hardwareInterface>
    </actuator>
  </transmission>
  
  <link
    name="RL_mid_connector_link">
    <inertial>
      <origin
        xyz="0 0.025165065848375 -0.00803311644068054"
        rpy="0 0 0" />
      <mass
        value="0.111218290944422" />
      <inertia
        ixx="4.72825951749508E-05"
        ixy="3.30759716400942E-22"
        ixz="1.85365958576505E-21"
        iyy="4.15796957339013E-05"
        iyz="8.78847811785193E-06"
        izz="4.15796957339012E-05" />
    </inertial>
    <visual>
      <origin
        xyz="0 0 0"
        rpy="0 0 0" />
      <geometry>
        <mesh
          filename="package://optimus/meshes/RL_mid_connector_link.STL" />
      </geometry>
      <material
        name="">
        <color
          rgba="0.792156862745098 0.819607843137255 0.933333333333333 1" />
      </material>
    </visual>
    <collision>
      <origin
        xyz="0 0 0"
        rpy="0 0 0" />
      <geometry>
        <mesh
          filename="package://optimus/meshes/RL_mid_connector_link.STL" />
      </geometry>
    </collision>
  </link>
  
  <joint
    name="RL_mid_connector_joint"
    type="fixed">
    <origin
      xyz="-0.25402097517419 0.127 0.16700000001"
      rpy="0 0 0" />
    <parent
      link="chassis_link" />
    <child
      link="RL_mid_connector_link" />
    <axis
      xyz="0 0 0" />
  </joint>
  
  <link
    name="RL_wheel_connector_link">
    <inertial>
      <origin
        xyz="-6.65646850279145E-05 0.0094812987297358 -0.025165065848375"
        rpy="0 0 0" />
      <mass
        value="0.111218290944422" />
      <inertia
        ixx="4.72825951749508E-05"
        ixy="4.53719304107114E-21"
        ixz="-9.96908056445756E-22"
        iyy="4.15796957339013E-05"
        iyz="8.78847811785192E-06"
        izz="4.15796957339012E-05" />
    </inertial>
    <visual>
      <origin
        xyz="0 0 0"
        rpy="0 0 0" />
      <geometry>
        <mesh
          filename="package://optimus/meshes/RL_wheel_connector_link.STL" />
      </geometry>
      <material
        name="">
        <color
          rgba="0.792156862745098 0.819607843137255 0.933333333333333 1" />
      </material>
    </visual>
    <collision>
      <origin
        xyz="0 0 0"
        rpy="0 0 0" />
      <geometry>
        <mesh
          filename="package://optimus/meshes/RL_wheel_connector_link.STL" />
      </geometry>
    </collision>
  </link>
  
  <joint
    name="RL_wheel_connector_joint"
    type="fixed">
    <origin
      xyz="6.656468502797E-05 0.0317499999999999 -0.0331981822890556"
      rpy="0 0 0" />
    <parent
      link="RL_mid_connector_link" />
    <child
      link="RL_wheel_connector_link" />
    <axis
      xyz="0 0 0" />
  </joint>
  
  <link
    name="RL_wheel_link">
    <inertial>
      <origin
        xyz="2.77555756156289E-16 0.0381 0"
        rpy="0 0 0" />
      <mass
        value="1.37478617203279" />
      <inertia
        ixx="0.00468685600007826"
        ixy="6.23781132713421E-19"
        ixz="2.59403840096632E-18"
        iyy="0.00804327643003351"
        iyz="1.35884787850143E-18"
        izz="0.00468685600007826" />
    </inertial>
    <visual>
      <origin
        xyz="0 0 0"
        rpy="0 0 0" />
      <geometry>
        <mesh
          filename="package://optimus/meshes/RL_wheel_link.STL" />
      </geometry>
      <material
        name="">
        <color
          rgba="0.792156862745098 0.819607843137255 0.933333333333333 1" />
      </material>
    </visual>
    <collision>
      <origin
        xyz="0 0 0"
        rpy="0 0 0" />
      <geometry>
        <mesh
          filename="package://optimus/meshes/RL_wheel_link.STL" />
      </geometry>
    </collision>
  </link>
  
  <joint
    name="RL_wheel_joint"
    type="continuous">
    <origin
      xyz="-6.65646850279145E-05 0.0346463645781108 -0.0331981822890555"
      rpy="0 0 0" />
    <parent
      link="RL_wheel_connector_link" />
    <child
      link="RL_wheel_link" />
    <axis
      xyz="0 1 0" />
  </joint>

  <transmission name="RL_wheel_trans">
    <type>transmission_interface/SimpleTransmission</type>
    <joint name="RL_wheel_joint">
      <hardwareInterface>hardware_interface/VelocityJointInterface</hardwareInterface>
    </joint>
    <actuator name="RL_wheel_actuator">
      <mechanicalReduction>1</mechanicalReduction>
      <hardwareInterface>hardware_interface/VelocityJointInterface</hardwareInterface>
    </actuator>
  </transmission>

  <gazebo reference="chassis_link">
    <material>Gazebo/Grey</material>
  </gazebo>

  <gazebo reference="FL_wheel_link">
    <material>Gazebo/DarkGrey</material>
  </gazebo>
  <gazebo reference="FL_mid_connector_link">
    <material>Gazebo/Red</material>
  </gazebo>
  <gazebo reference="FL_wheel_connector_link">
    <material>Gazebo/Red</material>
  </gazebo>

  <gazebo reference="FR_wheel_link">
    <material>Gazebo/DarkGrey</material>
  </gazebo>
  <gazebo reference="FR_mid_connector_link">
    <material>Gazebo/Red</material>
  </gazebo>
  <gazebo reference="FR_wheel_connector_link">
    <material>Gazebo/Red</material>
  </gazebo>

  <gazebo reference="RL_wheel_link">
    <material>Gazebo/DarkGrey</material>
  </gazebo>
  <gazebo reference="RL_mid_connector_link">
    <material>Gazebo/Red</material>
  </gazebo>
  <gazebo reference="RL_wheel_connector_link">
    <material>Gazebo/Red</material>
  </gazebo>

  <gazebo reference="RR_wheel_link">
    <material>Gazebo/DarkGrey</material>
  </gazebo>
  <gazebo reference="RR_mid_connector_link">
    <material>Gazebo/Red</material>
  </gazebo>
  <gazebo reference="RR_wheel_connector_link">
    <material>Gazebo/Red</material>
  </gazebo>

</robot>