<?xml version="1.0" encoding="utf-8"?>
<!-- This URDF was automatically created by SolidWorks to URDF Exporter! Originally created by Stephen Brawner (brawner@gmail.com) 
     Commit Version: 1.6.0-1-g15f4949  Build Version: 1.6.7594.29634
     For more information, please see http://wiki.ros.org/sw_urdf_exporter -->
<robot
  name="optimus_no_origin_change">
  <link
    name="base_link">
    <inertial>
      <origin
        xyz="0.000271978105834902 0 -0.1"
        rpy="0 0 0" />
      <mass
        value="144.386284511659" />
      <inertia
        ixx="0.989799028466643"
        ixy="-4.90168172178078E-16"
        ixz="-3.9037651168657E-16"
        iyy="11.5644597125907"
        iyz="1.3263541125631E-17"
        izz="11.5261415106454" />
    </inertial>
    <visual>
      <origin
        xyz="0 0 0"
        rpy="0 0 0" />
      <geometry>
        <mesh
          filename="package://optimus_no_origin_change/meshes/base_link.STL" />
      </geometry>
      <material
        name="">
        <color
          rgba="0.792156862745098 0.819607843137255 0.933333333333333 1" />
      </material>
    </visual>
    <collision>
      <origin
        xyz="0 0 0"
        rpy="0 0 0" />
      <geometry>
        <mesh
          filename="package://optimus_no_origin_change/meshes/base_link.STL" />
      </geometry>
    </collision>
  </link>
  <link
    name="F_bogie_link">
    <inertial>
      <origin
        xyz="-0.0244164389508556 1.11022302462516E-16 0.3"
        rpy="0 0 0" />
      <mass
        value="75.1415926535898" />
      <inertia
        ixx="3.32158725212812"
        ixy="1.03837403218471E-16"
        ixz="-2.69176304497067E-16"
        iyy="5.32245435921457"
        iyz="-4.98335187950695E-16"
        izz="2.49354029185103" />
    </inertial>
    <visual>
      <origin
        xyz="0 0 0"
        rpy="0 0 0" />
      <geometry>
        <mesh
          filename="package://optimus_no_origin_change/meshes/F_bogie_link.STL" />
      </geometry>
      <material
        name="">
        <color
          rgba="0.792156862745098 0.819607843137255 0.933333333333333 1" />
      </material>
    </visual>
    <collision>
      <origin
        xyz="0 0 0"
        rpy="0 0 0" />
      <geometry>
        <mesh
          filename="package://optimus_no_origin_change/meshes/F_bogie_link.STL" />
      </geometry>
    </collision>
  </link>
  <joint
    name="F_bogie_joint"
    type="fixed">
    <origin
      xyz="1.1 -0.3 -0.1"
      rpy="-1.5707963267949 0 0" />
    <parent
      link="base_link" />
    <child
      link="F_bogie_link" />
    <axis
      xyz="0 0 0" />
  </joint>
  <link
    name="FR_outer_wheel_connector_link">
    <inertial>
      <origin
        xyz="3.33066907387547E-15 -2.85882428840978E-15 0.206818181818182"
        rpy="0 0 0" />
      <mass
        value="2.07345115136926" />
      <inertia
        ixx="0.0307163509718099"
        ixy="0"
        ixz="-3.74779761372748E-17"
        iyy="0.0307163509718099"
        iyz="2.33586732760321E-17"
        izz="0.00162106180925233" />
    </inertial>
    <visual>
      <origin
        xyz="0 0 0"
        rpy="0 0 0" />
      <geometry>
        <mesh
          filename="package://optimus_no_origin_change/meshes/FR_outer_wheel_connector_link.STL" />
      </geometry>
      <material
        name="">
        <color
          rgba="0.792156862745098 0.819607843137255 0.933333333333333 1" />
      </material>
    </visual>
    <collision>
      <origin
        xyz="0 0 0"
        rpy="0 0 0" />
      <geometry>
        <mesh
          filename="package://optimus_no_origin_change/meshes/FR_outer_wheel_connector_link.STL" />
      </geometry>
    </collision>
  </link>
  <joint
    name="FR_outer_wheel_connector_joint"
    type="fixed">
    <origin
      xyz="0.2 0 0.6"
      rpy="0 0 -1.3038" />
    <parent
      link="F_bogie_link" />
    <child
      link="FR_outer_wheel_connector_link" />
    <axis
      xyz="0 0 0" />
  </joint>
  <link
    name="FR_outer_wheel_link">
    <inertial>
      <origin
        xyz="0.201565805423125 -2.39341393715176E-06 2.39491226172728E-06"
        rpy="0 0 0" />
      <mass
        value="39.6885330149725" />
      <inertia
        ixx="4.63080044138697"
        ixy="5.39282947462053E-06"
        ixz="-5.40463680082042E-06"
        iyy="2.95668276005804"
        iyz="-9.49566603791752E-06"
        izz="2.95668280949652" />
    </inertial>
    <visual>
      <origin
        xyz="0 0 0"
        rpy="0 0 0" />
      <geometry>
        <mesh
          filename="package://optimus_no_origin_change/meshes/FR_outer_wheel_link.STL" />
      </geometry>
      <material
        name="">
        <color
          rgba="0.792156862745098 0.819607843137255 0.933333333333333 1" />
      </material>
    </visual>
    <collision>
      <origin
        xyz="0 0 0"
        rpy="0 0 0" />
      <geometry>
        <mesh
          filename="package://optimus_no_origin_change/meshes/FR_outer_wheel_link.STL" />
      </geometry>
    </collision>
  </link>
  <joint
    name="FR_outer_wheel_joint"
    type="continuous">
    <origin
      xyz="0 0 0.326743890579709"
      rpy="1.85261522674577 -1.5707963267949 0" />
    <parent
      link="FR_outer_wheel_connector_link" />
    <child
      link="FR_outer_wheel_link" />
    <axis
      xyz="1 0 0" />
  </joint>
  <link
    name="FL_outer_wheel_connector_link">
    <inertial>
      <origin
        xyz="3.33066907387547E-15 8.21565038222616E-15 0.206818181818182"
        rpy="0 0 0" />
      <mass
        value="2.07345115136926" />
      <inertia
        ixx="0.0307163509718099"
        ixy="0"
        ixz="-2.7143033242461E-17"
        iyy="0.0307163509718099"
        iyz="-6.90946420908297E-18"
        izz="0.00162106180925233" />
    </inertial>
    <visual>
      <origin
        xyz="0 0 0"
        rpy="0 0 0" />
      <geometry>
        <mesh
          filename="package://optimus_no_origin_change/meshes/FL_outer_wheel_connector_link.STL" />
      </geometry>
      <material
        name="">
        <color
          rgba="0.792156862745098 0.819607843137255 0.933333333333333 1" />
      </material>
    </visual>
    <collision>
      <origin
        xyz="0 0 0"
        rpy="0 0 0" />
      <geometry>
        <mesh
          filename="package://optimus_no_origin_change/meshes/FL_outer_wheel_connector_link.STL" />
      </geometry>
    </collision>
  </link>
  <joint
    name="FL_outer_wheel_connector_joint"
    type="fixed">
    <origin
      xyz="0.2 0 0"
      rpy="3.1416 0 -1.0332" />
    <parent
      link="F_bogie_link" />
    <child
      link="FL_outer_wheel_connector_link" />
    <axis
      xyz="0 0 0" />
  </joint>
  <link
    name="FL_outer_wheel__link">
    <inertial>
      <origin
        xyz="0.201565805423117 -2.39341393393211E-06 2.39491227418953E-06"
        rpy="0 0 0" />
      <mass
        value="39.6885330149755" />
      <inertia
        ixx="4.63080044138726"
        ixy="5.39282947359885E-06"
        ixz="-5.40463679747915E-06"
        iyy="2.9566827600579"
        iyz="-9.49566611097019E-06"
        izz="2.95668280949706" />
    </inertial>
    <visual>
      <origin
        xyz="0 0 0"
        rpy="0 0 0" />
      <geometry>
        <mesh
          filename="package://optimus_no_origin_change/meshes/FL_outer_wheel__link.STL" />
      </geometry>
      <material
        name="">
        <color
          rgba="0.792156862745098 0.819607843137255 0.933333333333333 1" />
      </material>
    </visual>
    <collision>
      <origin
        xyz="0 0 0"
        rpy="0 0 0" />
      <geometry>
        <mesh
          filename="package://optimus_no_origin_change/meshes/FL_outer_wheel__link.STL" />
      </geometry>
    </collision>
  </link>
  <joint
    name="FL_outer_wheel_joint"
    type="continuous">
    <origin
      xyz="0 0 0.326743890579708"
      rpy="1.85261522674577 -1.5707963267949 0" />
    <parent
      link="FL_outer_wheel_connector_link" />
    <child
      link="FL_outer_wheel__link" />
    <axis
      xyz="1 0 0" />
  </joint>
  <link
    name="R_bogie_link">
    <inertial>
      <origin
        xyz="-0.0244164389508561 -1.11022302462516E-16 -0.3"
        rpy="0 0 0" />
      <mass
        value="75.1415926535897" />
      <inertia
        ixx="3.32158725212812"
        ixy="4.90010961927251E-17"
        ixz="9.65658784720791E-17"
        iyy="5.32245435921456"
        iyz="8.52304382823977E-17"
        izz="2.49354029185103" />
    </inertial>
    <visual>
      <origin
        xyz="0 0 0"
        rpy="0 0 0" />
      <geometry>
        <mesh
          filename="package://optimus_no_origin_change/meshes/R_bogie_link.STL" />
      </geometry>
      <material
        name="">
        <color
          rgba="0.792156862745098 0.819607843137255 0.933333333333333 1" />
      </material>
    </visual>
    <collision>
      <origin
        xyz="0 0 0"
        rpy="0 0 0" />
      <geometry>
        <mesh
          filename="package://optimus_no_origin_change/meshes/R_bogie_link.STL" />
      </geometry>
    </collision>
  </link>
  <joint
    name="R_bogie_joint"
    type="fixed">
    <origin
      xyz="-1.1 -0.3 -0.0999999999999984"
      rpy="-1.5707963267949 0 -3.14159265358979" />
    <parent
      link="base_link" />
    <child
      link="R_bogie_link" />
    <axis
      xyz="0 0 0" />
  </joint>
  <link
    name="RL_outer_wheel_connector_link">
    <inertial>
      <origin
        xyz="1.11022302462516E-16 -4.44089209850063E-16 0.206818181818182"
        rpy="0 0 0" />
      <mass
        value="2.07345115136926" />
      <inertia
        ixx="0.0307163509718099"
        ixy="-2.16840434497101E-18"
        ixz="-2.59961384249049E-17"
        iyy="0.0307163509718099"
        iyz="-1.02299443094433E-17"
        izz="0.00162106180925233" />
    </inertial>
    <visual>
      <origin
        xyz="0 0 0"
        rpy="0 0 0" />
      <geometry>
        <mesh
          filename="package://optimus_no_origin_change/meshes/RL_outer_wheel_connector_link.STL" />
      </geometry>
      <material
        name="">
        <color
          rgba="0.792156862745098 0.819607843137255 0.933333333333333 1" />
      </material>
    </visual>
    <collision>
      <origin
        xyz="0 0 0"
        rpy="0 0 0" />
      <geometry>
        <mesh
          filename="package://optimus_no_origin_change/meshes/RL_outer_wheel_connector_link.STL" />
      </geometry>
    </collision>
  </link>
  <joint
    name="RL_outer_wheel_connector_joint"
    type="fixed">
    <origin
      xyz="0.2 0 -0.6"
      rpy="3.1416 0 -1.7592" />
    <parent
      link="R_bogie_link" />
    <child
      link="RL_outer_wheel_connector_link" />
    <axis
      xyz="0 0 0" />
  </joint>
  <link
    name="RL_outer_wheel_link">
    <inertial>
      <origin
        xyz="0.201565805282954 -2.39346774866256E-06 2.39471855190132E-06"
        rpy="0 0 0" />
      <mass
        value="39.6885328227854" />
      <inertia
        ixx="4.63080044108311"
        ixy="5.39285840694666E-06"
        ixz="-5.4045010386314E-06"
        iyy="2.95668275970754"
        iyz="-9.49559167129355E-06"
        izz="2.95668280940998" />
    </inertial>
    <visual>
      <origin
        xyz="0 0 0"
        rpy="0 0 0" />
      <geometry>
        <mesh
          filename="package://optimus_no_origin_change/meshes/RL_outer_wheel_link.STL" />
      </geometry>
      <material
        name="">
        <color
          rgba="0.792156862745098 0.819607843137255 0.933333333333333 1" />
      </material>
    </visual>
    <collision>
      <origin
        xyz="0 0 0"
        rpy="0 0 0" />
      <geometry>
        <mesh
          filename="package://optimus_no_origin_change/meshes/RL_outer_wheel_link.STL" />
      </geometry>
    </collision>
  </link>
  <joint
    name="RL_outer_wheel_joint"
    type="continuous">
    <origin
      xyz="0 0 0.326743890579709"
      rpy="1.85261522674576 -1.5707963267949 0" />
    <parent
      link="RL_outer_wheel_connector_link" />
    <child
      link="RL_outer_wheel_link" />
    <axis
      xyz="1 0 0" />
  </joint>
  <link
    name="RR_outer_wheel_connector_link">
    <inertial>
      <origin
        xyz="5.55111512312578E-16 -8.88178419700125E-16 0.206818181818182"
        rpy="0 0 0" />
      <mass
        value="2.07345115136926" />
      <inertia
        ixx="0.0307163509718099"
        ixy="-3.46944695195361E-18"
        ixz="-1.69209866544731E-17"
        iyy="0.0307163509718099"
        iyz="-9.04307851299227E-18"
        izz="0.00162106180925233" />
    </inertial>
    <visual>
      <origin
        xyz="0 0 0"
        rpy="0 0 0" />
      <geometry>
        <mesh
          filename="package://optimus_no_origin_change/meshes/RR_outer_wheel_connector_link.STL" />
      </geometry>
      <material
        name="">
        <color
          rgba="0.792156862745098 0.819607843137255 0.933333333333333 1" />
      </material>
    </visual>
    <collision>
      <origin
        xyz="0 0 0"
        rpy="0 0 0" />
      <geometry>
        <mesh
          filename="package://optimus_no_origin_change/meshes/RR_outer_wheel_connector_link.STL" />
      </geometry>
    </collision>
  </link>
  <joint
    name="RR_outer_wheel_connector_joint"
    type="fixed">
    <origin
      xyz="0.2 0 0"
      rpy="0 0 -2.2505" />
    <parent
      link="R_bogie_link" />
    <child
      link="RR_outer_wheel_connector_link" />
    <axis
      xyz="0 0 0" />
  </joint>
  <link
    name="RR_outer_wheel_link">
    <inertial>
      <origin
        xyz="0.201565805423126 -2.39341393715176E-06 2.39491226405875E-06"
        rpy="0 0 0" />
      <mass
        value="39.6885330149728" />
      <inertia
        ixx="4.630800441387"
        ixy="5.39282946622436E-06"
        ixz="-5.40463679225832E-06"
        iyy="2.95668276005781"
        iyz="-9.49566595909168E-06"
        izz="2.95668280949678" />
    </inertial>
    <visual>
      <origin
        xyz="0 0 0"
        rpy="0 0 0" />
      <geometry>
        <mesh
          filename="package://optimus_no_origin_change/meshes/RR_outer_wheel_link.STL" />
      </geometry>
      <material
        name="">
        <color
          rgba="0.792156862745098 0.819607843137255 0.933333333333333 1" />
      </material>
    </visual>
    <collision>
      <origin
        xyz="0 0 0"
        rpy="0 0 0" />
      <geometry>
        <mesh
          filename="package://optimus_no_origin_change/meshes/RR_outer_wheel_link.STL" />
      </geometry>
    </collision>
  </link>
  <joint
    name="RR_outer_wheel_joint"
    type="continuous">
    <origin
      xyz="0 0 0.326743890579708"
      rpy="1.85261522674574 -1.5707963267949 0" />
    <parent
      link="RR_outer_wheel_connector_link" />
    <child
      link="RR_outer_wheel_link" />
    <axis
      xyz="1 0 0" />
  </joint>
  <link
    name="FL_inner_wheel_connector_link">
    <inertial>
      <origin
        xyz="0.000744286749609024 1.11022302462516E-16 0.20508770745258"
        rpy="0 0 0" />
      <mass
        value="3.16570796326795" />
      <inertia
        ixx="0.0524105342655653"
        ixy="-4.35624452410736E-20"
        ixz="0.000247607077286725"
        iyy="0.0471742267451069"
        iyz="1.2697749470794E-19"
        izz="0.00666180087935192" />
    </inertial>
    <visual>
      <origin
        xyz="0 0 0"
        rpy="0 0 0" />
      <geometry>
        <mesh
          filename="package://optimus_no_origin_change/meshes/FL_inner_wheel_connector_link.STL" />
      </geometry>
      <material
        name="">
        <color
          rgba="0.792156862745098 0.819607843137255 0.933333333333333 1" />
      </material>
    </visual>
    <collision>
      <origin
        xyz="0 0 0"
        rpy="0 0 0" />
      <geometry>
        <mesh
          filename="package://optimus_no_origin_change/meshes/FL_inner_wheel_connector_link.STL" />
      </geometry>
    </collision>
  </link>
  <joint
    name="FL_inner_wheel_connector_joint"
    type="fixed">
    <origin
      xyz="0.15 0.265 -0.1"
      rpy="1.5708 0 1.5708" />
    <parent
      link="base_link" />
    <child
      link="FL_inner_wheel_connector_link" />
    <axis
      xyz="0 0 0" />
  </joint>
  <link
    name="FL_inner_wheel_link">
    <inertial>
      <origin
        xyz="0.122556778342617 -2.36936965991585E-06 2.37036620520659E-06"
        rpy="0 0 0" />
      <mass
        value="5.0050487689712" />
      <inertia
        ixx="0.144720367774976"
        ixy="1.68525920626152E-07"
        ixz="-1.68894899705309E-07"
        iyy="0.0924066661076408"
        iyz="-2.96739585987828E-07"
        izz="0.0924066676526247" />
    </inertial>
    <visual>
      <origin
        xyz="0 0 0"
        rpy="0 0 0" />
      <geometry>
        <mesh
          filename="package://optimus_no_origin_change/meshes/FL_inner_wheel_link.STL" />
      </geometry>
      <material
        name="">
        <color
          rgba="0.792156862745098 0.819607843137255 0.933333333333333 1" />
      </material>
    </visual>
    <collision>
      <origin
        xyz="0 0 0"
        rpy="0 0 0" />
      <geometry>
        <mesh
          filename="package://optimus_no_origin_change/meshes/FL_inner_wheel_link.STL" />
      </geometry>
    </collision>
  </link>
  <joint
    name="FL_inner_wheel_joint"
    type="continuous">
    <origin
      xyz="-0.0250000000000001 0 0.32"
      rpy="-3.08118480125405 0 3.14159265358979" />
    <parent
      link="FL_inner_wheel_connector_link" />
    <child
      link="FL_inner_wheel_link" />
    <axis
      xyz="1 0 0" />
  </joint>
  <link
    name="FR_inner_wheel_connector_link">
    <inertial>
      <origin
        xyz="0.000744286749609135 -1.11022302462516E-16 0.20508770745258"
        rpy="0 0 0" />
      <mass
        value="3.16570796326795" />
      <inertia
        ixx="0.0524105342655651"
        ixy="-1.50859814025046E-18"
        ixz="0.000247607077286713"
        iyy="0.0471742267451067"
        iyz="1.12195712810502E-18"
        izz="0.0066618008793519" />
    </inertial>
    <visual>
      <origin
        xyz="0 0 0"
        rpy="0 0 0" />
      <geometry>
        <mesh
          filename="package://optimus_no_origin_change/meshes/FR_inner_wheel_connector_link.STL" />
      </geometry>
      <material
        name="">
        <color
          rgba="0.792156862745098 0.819607843137255 0.933333333333333 1" />
      </material>
    </visual>
    <collision>
      <origin
        xyz="0 0 0"
        rpy="0 0 0" />
      <geometry>
        <mesh
          filename="package://optimus_no_origin_change/meshes/FR_inner_wheel_connector_link.STL" />
      </geometry>
    </collision>
  </link>
  <joint
    name="FR_inner_wheel_connector_joint"
    type="fixed">
    <origin
      xyz="0.15 -0.265 -0.1"
      rpy="-1.5708 0 -1.5708" />
    <parent
      link="base_link" />
    <child
      link="FR_inner_wheel_connector_link" />
    <axis
      xyz="0 0 0" />
  </joint>
  <link
    name="FR_inner_wheel_link">
    <inertial>
      <origin
        xyz="0.122556779088169 -2.3693696860061E-06 2.37036622774411E-06"
        rpy="0 0 0" />
      <mass
        value="5.00504892402194" />
      <inertia
        ixx="0.144720367920832"
        ixy="1.68525902114553E-07"
        ixz="-1.68894881016372E-07"
        iyy="0.0924066662947163"
        iyz="-2.96738910159078E-07"
        izz="0.0924066676638247" />
    </inertial>
    <visual>
      <origin
        xyz="0 0 0"
        rpy="0 0 0" />
      <geometry>
        <mesh
          filename="package://optimus_no_origin_change/meshes/FR_inner_wheel_link.STL" />
      </geometry>
      <material
        name="">
        <color
          rgba="0.792156862745098 0.819607843137255 0.933333333333333 1" />
      </material>
    </visual>
    <collision>
      <origin
        xyz="0 0 0"
        rpy="0 0 0" />
      <geometry>
        <mesh
          filename="package://optimus_no_origin_change/meshes/FR_inner_wheel_link.STL" />
      </geometry>
    </collision>
  </link>
  <joint
    name="FR_inner_wheel_joint"
    type="continuous">
    <origin
      xyz="-0.0249999999999999 0 0.32"
      rpy="2.2011440774755 0 3.14159265358979" />
    <parent
      link="FR_inner_wheel_connector_link" />
    <child
      link="FR_inner_wheel_link" />
    <axis
      xyz="1 0 0" />
  </joint>
  <link
    name="RL_inner_wheel_connector_link">
    <inertial>
      <origin
        xyz="0.000744286749609135 0 0.20508770745258"
        rpy="0 0 0" />
      <mass
        value="3.16570796326795" />
      <inertia
        ixx="0.0524105342655653"
        ixy="1.32871259208305E-18"
        ixz="0.000247607077286719"
        iyy="0.0471742267451069"
        iyz="-7.36016907127747E-18"
        izz="0.00666180087935194" />
    </inertial>
    <visual>
      <origin
        xyz="0 0 0"
        rpy="0 0 0" />
      <geometry>
        <mesh
          filename="package://optimus_no_origin_change/meshes/RL_inner_wheel_connector_link.STL" />
      </geometry>
      <material
        name="">
        <color
          rgba="0.792156862745098 0.819607843137255 0.933333333333333 1" />
      </material>
    </visual>
    <collision>
      <origin
        xyz="0 0 0"
        rpy="0 0 0" />
      <geometry>
        <mesh
          filename="package://optimus_no_origin_change/meshes/RL_inner_wheel_connector_link.STL" />
      </geometry>
    </collision>
  </link>
  <joint
    name="RL_inner_wheel_connector_joint"
    type="fixed">
    <origin
      xyz="-0.15 0.265 -0.1"
      rpy="-1.5708 0 1.5708" />
    <parent
      link="base_link" />
    <child
      link="RL_inner_wheel_connector_link" />
    <axis
      xyz="0 0 0" />
  </joint>
  <link
    name="RL_inner_wheel_link">
    <inertial>
      <origin
        xyz="2.12477262673261E-06 -2.59188923523723E-06 0.122556778342622"
        rpy="0 0 0" />
      <mass
        value="5.00504876897168" />
      <inertia
        ixx="0.0924066080403615"
        ixy="-2.90848497870935E-07"
        ixz="-1.51099176154497E-07"
        iyy="0.0924067257199195"
        iyz="1.84649701303913E-07"
        izz="0.144720367774988" />
    </inertial>
    <visual>
      <origin
        xyz="0 0 0"
        rpy="0 0 0" />
      <geometry>
        <mesh
          filename="package://optimus_no_origin_change/meshes/RL_inner_wheel_link.STL" />
      </geometry>
      <material
        name="">
        <color
          rgba="0.792156862745098 0.819607843137255 0.933333333333333 1" />
      </material>
    </visual>
    <collision>
      <origin
        xyz="0 0 0"
        rpy="0 0 0" />
      <geometry>
        <mesh
          filename="package://optimus_no_origin_change/meshes/RL_inner_wheel_link.STL" />
      </geometry>
    </collision>
  </link>
  <joint
    name="RL_inner_wheel_joint"
    type="continuous">
    <origin
      xyz="-0.0249999999999979 0 0.32"
      rpy="1.5707963267949 -0.0864704456326401 -1.5707963267949" />
    <parent
      link="RL_inner_wheel_connector_link" />
    <child
      link="RL_inner_wheel_link" />
    <axis
      xyz="0 0 1" />
  </joint>
  <link
    name="RR_inner_wheel_connector_link">
    <inertial>
      <origin
        xyz="0.000744286749609135 1.11022302462516E-16 0.20508770745258"
        rpy="0 0 0" />
      <mass
        value="3.16570796326795" />
      <inertia
        ixx="0.0524105342655651"
        ixy="2.77966142619567E-19"
        ixz="0.000247607077286714"
        iyy="0.0471742267451067"
        iyz="-3.33587796479693E-18"
        izz="0.00666180087935192" />
    </inertial>
    <visual>
      <origin
        xyz="0 0 0"
        rpy="0 0 0" />
      <geometry>
        <mesh
          filename="package://optimus_no_origin_change/meshes/RR_inner_wheel_connector_link.STL" />
      </geometry>
      <material
        name="">
        <color
          rgba="0.792156862745098 0.819607843137255 0.933333333333333 1" />
      </material>
    </visual>
    <collision>
      <origin
        xyz="0 0 0"
        rpy="0 0 0" />
      <geometry>
        <mesh
          filename="package://optimus_no_origin_change/meshes/RR_inner_wheel_connector_link.STL" />
      </geometry>
    </collision>
  </link>
  <joint
    name="RR_inner_wheel_connector_joint"
    type="fixed">
    <origin
      xyz="-0.149999999999999 -0.265 -0.0999999999999999"
      rpy="1.5707963267949 0 -1.5707963267949" />
    <parent
      link="base_link" />
    <child
      link="RR_inner_wheel_connector_link" />
    <axis
      xyz="0 0 0" />
  </joint>
  <link
    name="RR_inner_wheel_link">
    <inertial>
      <origin
        xyz="2.12477264605049E-06 -2.59188926099441E-06 0.122556779088174"
        rpy="0 0 0" />
      <mass
        value="5.00504892402154" />
      <inertia
        ixx="0.0924066082258415"
        ixy="-2.90865069290519E-07"
        ixz="-1.51099158833888E-07"
        iyy="0.0924067257326864"
        iyz="1.84649680710438E-07"
        izz="0.144720367920822" />
    </inertial>
    <visual>
      <origin
        xyz="0 0 0"
        rpy="0 0 0" />
      <geometry>
        <mesh
          filename="package://optimus_no_origin_change/meshes/RR_inner_wheel_link.STL" />
      </geometry>
      <material
        name="">
        <color
          rgba="0.792156862745098 0.819607843137255 0.933333333333333 1" />
      </material>
    </visual>
    <collision>
      <origin
        xyz="0 0 0"
        rpy="0 0 0" />
      <geometry>
        <mesh
          filename="package://optimus_no_origin_change/meshes/RR_inner_wheel_link.STL" />
      </geometry>
    </collision>
  </link>
  <joint
    name="RR_inner_wheel_joint"
    type="continuous">
    <origin
      xyz="-0.0249999999999991 0 0.32"
      rpy="1.5707963267949 -0.846919764335258 -1.5707963267949" />
    <parent
      link="RR_inner_wheel_connector_link" />
    <child
      link="RR_inner_wheel_link" />
    <axis
      xyz="0 0 1" />
  </joint>
</robot>