<?xml version="1.0" encoding="utf-8"?>
<!-- This URDF was automatically created by SolidWorks to URDF Exporter! Originally created by Stephen Brawner (brawner@gmail.com) 
     Commit Version: 1.6.0-1-g15f4949  Build Version: 1.6.7594.29634
     For more information, please see http://wiki.ros.org/sw_urdf_exporter -->
<robot
  name="optimus_corrected_origin" xmlns:xacro="http://ros.org/wiki/xacro">

  <!-- Bring in simulation data for Gazebo. -->
  <xacro:include filename="$(find optimus_corrected_origin)/urdf/optimus_corrected_origin.gazebo" />

  <link 
    name="base_link">
  </link>

  <joint name="base_link_joint" type="fixed">
    <origin xyz="0 0 0" rpy="0 0 0" />
    <parent link="base_link"/>
    <child link="chassis_link" />
  </joint>

  <link
    name="chassis_link">
    <inertial>
      <origin
        xyz="0.00027198 0 -0.1"
        rpy="0 0 0" />
      <mass
        value="144.39" />
      <inertia
        ixx="0.9898"
        ixy="-4.8728E-16"
        ixz="-3.8733E-16"
        iyy="11.564"
        iyz="1.3264E-17"
        izz="11.526" />
    </inertial>
    <visual>
      <origin
        xyz="0 0 0"
        rpy="0 0 0" />
      <geometry>
        <mesh
          filename="package://optimus_corrected_origin/meshes/chassis_link.STL" />
      </geometry>
      <material
        name="">
        <color
          rgba="0.79216 0.81961 0.93333 1" />
      </material>
    </visual>
    <collision>
      <origin
        xyz="0 0 0"
        rpy="0 0 0" />
      <geometry>
        <mesh
          filename="package://optimus_corrected_origin/meshes/chassis_link.STL" />
      </geometry>
    </collision>
  </link>

  
  <link
    name="F_bogie_link">
    <inertial>
      <origin
        xyz="-0.024416 2.2204E-16 -0.1"
        rpy="0 0 0" />
      <mass
        value="75.142" />
      <inertia
        ixx="3.3216"
        ixy="-2.8318E-16"
        ixz="-1.0263E-16"
        iyy="2.4935"
        iyz="-3.1203E-18"
        izz="5.3225" />
    </inertial>
    <visual>
      <origin
        xyz="0 0 0"
        rpy="0 0 0" />
      <geometry>
        <mesh
          filename="package://optimus_corrected_origin/meshes/F_bogie_link.STL" />
      </geometry>
      <material
        name="">
        <color
          rgba="0.79216 0.81961 0.93333 1" />
      </material>
    </visual>
    <collision>
      <origin
        xyz="0 0 0"
        rpy="0 0 0" />
      <geometry>
        <mesh
          filename="package://optimus_corrected_origin/meshes/F_bogie_link.STL" />
      </geometry>
    </collision>
  </link>

  <joint
    name="F_bogie_joint"
    type="fixed">
    <origin
      xyz="1.1 0 0"
      rpy="0 0 0" />
    <parent
      link="chassis_link" />
    <child
      link="F_bogie_link" />
    <axis
      xyz="0 0 0" />
  </joint>
  
  <link
    name="FR_outer_wheel_connector_link">
    <inertial>
      <origin
        xyz="-1.85268467234323E-15 0.206818181818182 4.10782519111308E-15"
        rpy="0 0 0" />
      <mass
        value="2.07345115136926" />
      <inertia
        ixx="0.0307163509718099"
        ixy="1.36572961430801E-17"
        ixz="3.68922553198698E-20"
        iyy="0.00162106180925233"
        iyz="-4.74701603502452E-17"
        izz="0.0307163509718099" />
    </inertial>
    <visual>
      <origin
        xyz="0 0 0"
        rpy="0 0 0" />
      <geometry>
        <mesh
          filename="package://optimus_corrected_origin/meshes/FR_outer_wheel_connector_link.STL" />
      </geometry>
      <material
        name="">
        <color
          rgba="0.792156862745098 0.819607843137255 0.933333333333333 1" />
      </material>
    </visual>
    <collision>
      <origin
        xyz="0 0 0"
        rpy="0 0 0" />
      <geometry>
        <mesh
          filename="package://optimus_corrected_origin/meshes/FR_outer_wheel_connector_link.STL" />
      </geometry>
    </collision>
  </link>

  <joint
    name="FR_outer_wheel_connector_joint"
    type="fixed">
    <origin
      xyz="0.2 0.3 -0.1"
      rpy="0 0 0" />
    <parent
      link="F_bogie_link" />
    <child
      link="FR_outer_wheel_connector_link" />
    <axis
      xyz="0 0 0" />
  </joint>
  
  <link
    name="FR_outer_wheel_link">
    <inertial>
      <origin
        xyz="7.94662217230846E-07 0.201565805423125 -3.29128348464103E-06"
        rpy="0 0 0" />
      <mass
        value="39.6885330149725" />
      <inertia
        ixx="2.95667434379043"
        ixy="-1.79772249602782E-06"
        ixz="-4.34948566726761E-06"
        iyy="4.63080044138697"
        iyz="7.42030339833979E-06"
        izz="2.95669122576413" />
    </inertial>
    <visual>
      <origin
        xyz="0 0 0"
        rpy="0 0 0" />
      <geometry>
        <mesh
          filename="package://optimus_corrected_origin/meshes/FR_outer_wheel_link.STL" />
      </geometry>
      <material
        name="">
        <color
          rgba="0.792156862745098 0.819607843137255 0.933333333333333 1" />
      </material>
    </visual>
    <collision>
      <origin
        xyz="0 0 0"
        rpy="0 0 0" />
      <geometry>
        <mesh
          filename="package://optimus_corrected_origin/meshes/FR_outer_wheel_link.STL" />
      </geometry>
    </collision>
  </link>

  <joint
    name="FR_outer_wheel_joint"
    type="continuous">
    <origin
      xyz="0 0.32674 0"
      rpy="0 0 0" />
    <parent
      link="FR_outer_wheel_connector_link" />
    <child
      link="FR_outer_wheel_link" />
    <axis
      xyz="0 1 0" />
  </joint>

  <transmission name="FR_outer_wheel_trans">
    <type>transmission_interface/SimpleTransmission</type>
    <joint name="FR_outer_wheel_joint">
      <hardwareInterface>hardware_interface/VelocityJointInterface</hardwareInterface>
    </joint>
    <actuator name="FR_outer_wheel_actuator">
      <mechanicalReduction>1</mechanicalReduction>
      <hardwareInterface>hardware_interface/VelocityJointInterface</hardwareInterface>
    </actuator>
  </transmission>
  
  <link
    name="FL_outer_wheel_connector_link">
    <inertial>
      <origin
        xyz="-5.37070388162419E-15 -0.206818181818182 6.77236045021345E-15"
        rpy="0 0 0" />
      <mass
        value="2.07345115136926" />
      <inertia
        ixx="0.0307163509718099"
        ixy="8.97759060052446E-18"
        ixz="-1.25952034604741E-19"
        iyy="0.00162106180925233"
        iyz="2.16951266466499E-17"
        izz="0.0307163509718099" />
    </inertial>
    <visual>
      <origin
        xyz="0 0 0"
        rpy="0 0 0" />
      <geometry>
        <mesh
          filename="package://optimus_corrected_origin/meshes/FL_outer_wheel_connector_link.STL" />
      </geometry>
      <material
        name="">
        <color
          rgba="0.792156862745098 0.819607843137255 0.933333333333333 1" />
      </material>
    </visual>
    <collision>
      <origin
        xyz="0 0 0"
        rpy="0 0 0" />
      <geometry>
        <mesh
          filename="package://optimus_corrected_origin/meshes/FL_outer_wheel_connector_link.STL" />
      </geometry>
    </collision>
  </link>

  <joint
    name="FL_outer_wheel_connector_joint"
    type="fixed">
    <origin
      xyz="0.2 -0.3 -0.1"
      rpy="0 0 0" />
    <parent
      link="F_bogie_link" />
    <child
      link="FL_outer_wheel_connector_link" />
    <axis
      xyz="0 0 0" />
  </joint>
  
  <link
    name="FL_outer_wheel_link">
    <inertial>
      <origin
        xyz="-2.92249659344934E-06 -0.201565805423117 -1.70969258106446E-06"
        rpy="0 0 0" />
      <mass
        value="39.6885330149755" />
      <inertia
        ixx="2.95668745449248"
        ixy="-6.59311314635011E-06"
        ixz="8.26813447856092E-06"
        iyy="4.63080044138726"
        iyz="-3.85013865752919E-06"
        izz="2.95667811506248" />
    </inertial>
    <visual>
      <origin
        xyz="0 0 0"
        rpy="0 0 0" />
      <geometry>
        <mesh
          filename="package://optimus_corrected_origin/meshes/FL_outer_wheel_link.STL" />
      </geometry>
      <material
        name="">
        <color
          rgba="0.792156862745098 0.819607843137255 0.933333333333333 1" />
      </material>
    </visual>
    <collision>
      <origin
        xyz="0 0 0"
        rpy="0 0 0" />
      <geometry>
        <mesh
          filename="package://optimus_corrected_origin/meshes/FL_outer_wheel_link.STL" />
      </geometry>
    </collision>
  </link>

  <joint
    name="FL_outer_wheel_joint"
    type="continuous">
    <origin
      xyz="0 -0.32674 0"
      rpy="0 0 0" />
    <parent
      link="FL_outer_wheel_connector_link" />
    <child
      link="FL_outer_wheel_link" />
    <axis
      xyz="0 -1 0" />
  </joint>

  <transmission name="FL_outer_wheel_trans">
    <type>transmission_interface/SimpleTransmission</type>
    <joint name="FL_outer_wheel_joint">
      <hardwareInterface>hardware_interface/VelocityJointInterface</hardwareInterface>
    </joint>
    <actuator name="FL_outer_wheel_actuator">
      <mechanicalReduction>1</mechanicalReduction>
      <hardwareInterface>hardware_interface/VelocityJointInterface</hardwareInterface>
    </actuator>
  </transmission>
  
  <link
    name="R_bogie_link">
    <inertial>
      <origin
        xyz="0.0244164389508561 1.11022302462516E-16 -0.0999999999999998"
        rpy="0 0 0" />
      <mass
        value="75.1415926535897" />
      <inertia
        ixx="3.32158725212812"
        ixy="1.04663201039582E-16"
        ixz="-6.0439083476423E-17"
        iyy="2.49354029185103"
        iyz="1.38285501712138E-16"
        izz="5.32245435921456" />
    </inertial>
    <visual>
      <origin
        xyz="0 0 0"
        rpy="0 0 0" />
      <geometry>
        <mesh
          filename="package://optimus_corrected_origin/meshes/R_bogie_link.STL" />
      </geometry>
      <material
        name="">
        <color
          rgba="0.792156862745098 0.819607843137255 0.933333333333333 1" />
      </material>
    </visual>
    <collision>
      <origin
        xyz="0 0 0"
        rpy="0 0 0" />
      <geometry>
        <mesh
          filename="package://optimus_corrected_origin/meshes/R_bogie_link.STL" />
      </geometry>
    </collision>
  </link>

  <joint
    name="R_bogie_joint"
    type="fixed">
    <origin
      xyz="-1.1 0 0"
      rpy="0 0 0" />
    <parent
      link="chassis_link" />
    <child
      link="R_bogie_link" />
    <axis
      xyz="0 0 0" />
  </joint>
  
  <link
    name="RL_outer_wheel_connector_link">
    <inertial>
      <origin
        xyz="-4.44089209850063E-16 0.206818181818182 2.22044604925031E-16"
        rpy="0 0 0" />
      <mass
        value="2.07345115136926" />
      <inertia
        ixx="0.0307163509718099"
        ixy="-1.54925599286273E-17"
        ixz="7.77880648044805E-20"
        iyy="0.00162106180925233"
        iyz="-2.30745184784673E-17"
        izz="0.0307163509718099" />
    </inertial>
    <visual>
      <origin
        xyz="0 0 0"
        rpy="0 0 0" />
      <geometry>
        <mesh
          filename="package://optimus_corrected_origin/meshes/RL_outer_wheel_connector_link.STL" />
      </geometry>
      <material
        name="">
        <color
          rgba="0.792156862745098 0.819607843137255 0.933333333333333 1" />
      </material>
    </visual>
    <collision>
      <origin
        xyz="0 0 0"
        rpy="0 0 0" />
      <geometry>
        <mesh
          filename="package://optimus_corrected_origin/meshes/RL_outer_wheel_connector_link.STL" />
      </geometry>
    </collision>
  </link>

  <joint
    name="RL_outer_wheel_connector_joint"
    type="fixed">
    <origin
      xyz="-0.2 0.3 -0.1"
      rpy="0 0 0" />
    <parent
      link="R_bogie_link" />
    <child
      link="RL_outer_wheel_connector_link" />
    <axis
      xyz="0 0 0" />
  </joint>
  
  <link
    name="RL_outer_wheel_link">
    <inertial>
      <origin
        xyz="1.05037916053874E-06 0.201565805282954 -3.21870601693863E-06"
        rpy="0 0 0" />
      <mass
        value="39.6885328227854" />
      <inertia
        ixx="2.95667512850444"
        ixy="-2.37453572280207E-06"
        ixz="-5.61709097472745E-06"
        iyy="4.63080044108311"
        iyz="7.25624788537814E-06"
        izz="2.95669044061308" />
    </inertial>
    <visual>
      <origin
        xyz="0 0 0"
        rpy="0 0 0" />
      <geometry>
        <mesh
          filename="package://optimus_corrected_origin/meshes/RL_outer_wheel_link.STL" />
      </geometry>
      <material
        name="">
        <color
          rgba="0.792156862745098 0.819607843137255 0.933333333333333 1" />
      </material>
    </visual>
    <collision>
      <origin
        xyz="0 0 0"
        rpy="0 0 0" />
      <geometry>
        <mesh
          filename="package://optimus_corrected_origin/meshes/RL_outer_wheel_link.STL" />
      </geometry>
    </collision>
  </link>

  <joint
    name="RL_outer_wheel_joint"
    type="continuous">
    <origin
      xyz="0 0.32674 0"
      rpy="0 0 0" />
    <parent
      link="RL_outer_wheel_connector_link" />
    <child
      link="RL_outer_wheel_link" />
    <axis
      xyz="0 1 0" />
  </joint>

  <transmission name="RL_outer_wheel_trans">
    <type>transmission_interface/SimpleTransmission</type>
    <joint name="RL_outer_wheel_joint">
      <hardwareInterface>hardware_interface/VelocityJointInterface</hardwareInterface>
    </joint>
    <actuator name="RL_outer_wheel_actuator">
      <mechanicalReduction>1</mechanicalReduction>
      <hardwareInterface>hardware_interface/VelocityJointInterface</hardwareInterface>
    </actuator>
  </transmission>
  
  <link
    name="RR_outer_wheel_connector_link">
    <inertial>
      <origin
        xyz="1.33226762955019E-15 -0.206818181818182 -1.11022302462516E-16"
        rpy="0 0 0" />
      <mass
        value="2.07345115136926" />
      <inertia
        ixx="0.0307163509718099"
        ixy="3.02822472609956E-18"
        ixz="1.04996792420079E-20"
        iyy="0.00162106180925233"
        iyz="1.93901600133467E-17"
        izz="0.0307163509718099" />
    </inertial>
    <visual>
      <origin
        xyz="0 0 0"
        rpy="0 0 0" />
      <geometry>
        <mesh
          filename="package://optimus_corrected_origin/meshes/RR_outer_wheel_connector_link.STL" />
      </geometry>
      <material
        name="">
        <color
          rgba="0.792156862745098 0.819607843137255 0.933333333333333 1" />
      </material>
    </visual>
    <collision>
      <origin
        xyz="0 0 0"
        rpy="0 0 0" />
      <geometry>
        <mesh
          filename="package://optimus_corrected_origin/meshes/RR_outer_wheel_connector_link.STL" />
      </geometry>
    </collision>
  </link>

  <joint
    name="RR_outer_wheel_connector_joint"
    type="fixed">
    <origin
      xyz="-0.2 -0.3 -0.1"
      rpy="0 0 0" />
    <parent
      link="R_bogie_link" />
    <child
      link="RR_outer_wheel_connector_link" />
    <axis
      xyz="0 0 0" />
  </joint>
  
  <link
    name="RR_outer_wheel_link">
    <inertial>
      <origin
        xyz="-3.13523784090108E-06 -0.201565805423125 -1.27840475139251E-06"
        rpy="0 0 0" />
      <mass
        value="39.6885330149728" />
      <inertia
        ixx="2.95668958616865"
        ixy="-7.07207631433677E-06"
        ixz="6.62641370626784E-06"
        iyy="4.630800441387"
        iyz="-2.87722872087634E-06"
        izz="2.95667598338593" />
    </inertial>
    <visual>
      <origin
        xyz="0 0 0"
        rpy="0 0 0" />
      <geometry>
        <mesh
          filename="package://optimus_corrected_origin/meshes/RR_outer_wheel_link.STL" />
      </geometry>
      <material
        name="">
        <color
          rgba="0.792156862745098 0.819607843137255 0.933333333333333 1" />
      </material>
    </visual>
    <collision>
      <origin
        xyz="0 0 0"
        rpy="0 0 0" />
      <geometry>
        <mesh
          filename="package://optimus_corrected_origin/meshes/RR_outer_wheel_link.STL" />
      </geometry>
    </collision>
  </link>

  <joint
    name="RR_outer_wheel_joint"
    type="continuous">
    <origin
      xyz="0 -0.32674 0"
      rpy="0 0 0" />
    <parent
      link="RR_outer_wheel_connector_link" />
    <child
      link="RR_outer_wheel_link" />
    <axis
      xyz="0 -1 0" />
  </joint>

  <transmission name="RR_outer_wheel_trans">
    <type>transmission_interface/SimpleTransmission</type>
    <joint name="RR_outer_wheel_joint">
      <hardwareInterface>hardware_interface/VelocityJointInterface</hardwareInterface>
    </joint>
    <actuator name="RR_outer_wheel_actuator">
      <mechanicalReduction>1</mechanicalReduction>
      <hardwareInterface>hardware_interface/VelocityJointInterface</hardwareInterface>
    </actuator>
  </transmission>
  
  <link
    name="FL_inner_wheel_connector_link">
    <inertial>
      <origin
        xyz="0.20508770745258 0.000744286749609024 -1.11022302462516E-16"
        rpy="0 0 0" />
      <mass
        value="3.16570796326795" />
      <inertia
        ixx="0.00666180087935192"
        ixy="0.000247607077286714"
        ixz="1.6098074917693E-19"
        iyy="0.0524105342655653"
        iyz="6.75526439645087E-19"
        izz="0.0471742267451069" />
    </inertial>
    <visual>
      <origin
        xyz="0 0 0"
        rpy="0 0 0" />
      <geometry>
        <mesh
          filename="package://optimus_corrected_origin/meshes/FL_inner_wheel_connector_link.STL" />
      </geometry>
      <material
        name="">
        <color
          rgba="0.792156862745098 0.819607843137255 0.933333333333333 1" />
      </material>
    </visual>
    <collision>
      <origin
        xyz="0 0 0"
        rpy="0 0 0" />
      <geometry>
        <mesh
          filename="package://optimus_corrected_origin/meshes/FL_inner_wheel_connector_link.STL" />
      </geometry>
    </collision>
  </link>

  <joint
    name="FL_inner_wheel_connector_joint"
    type="fixed">
    <origin
      xyz="0.15 0.265 -0.1"
      rpy="0 0 0" />
    <parent
      link="chassis_link" />
    <child
      link="FL_inner_wheel_connector_link" />
    <axis
      xyz="0 0 0" />
  </joint>
  
  <link
    name="FL_inner_wheel_link">
    <inertial>
      <origin
        xyz="-2.22300115826357E-06 -0.122556778342617 -2.50814959334988E-06"
        rpy="0 0 0" />
      <mass
        value="5.0050487689712" />
      <inertia
        ixx="0.0924066318833436"
        ixy="-1.58412736937296E-07"
        ixz="2.94669651268579E-07"
        iyy="0.144720367774976"
        iyz="-1.78414903657771E-07"
        izz="0.092406701876922" />
    </inertial>
    <visual>
      <origin
        xyz="0 0 0"
        rpy="0 0 0" />
      <geometry>
        <mesh
          filename="package://optimus_corrected_origin/meshes/FL_inner_wheel_link.STL" />
      </geometry>
      <material
        name="">
        <color
          rgba="0.792156862745098 0.819607843137255 0.933333333333333 1" />
      </material>
    </visual>
    <collision>
      <origin
        xyz="0 0 0"
        rpy="0 0 0" />
      <geometry>
        <mesh
          filename="package://optimus_corrected_origin/meshes/FL_inner_wheel_link.STL" />
      </geometry>
    </collision>
  </link>

  <joint
    name="FL_inner_wheel_joint"
    type="continuous">
    <origin
      xyz="0.32 -0.025 0"
      rpy="0 0 0" />
    <parent
      link="FL_inner_wheel_connector_link" />
    <child
      link="FL_inner_wheel_link" />
    <axis
      xyz="0 -1 0" />
  </joint>
  
  <link
    name="FR_inner_wheel_connector_link">
    <inertial>
      <origin
        xyz="0.20508770745258 -0.000744286749609135 1.11022302462516E-16"
        rpy="0 0 0" />
      <mass
        value="3.16570796326795" />
      <inertia
        ixx="0.0066618008793519"
        ixy="-0.000247607077286714"
        ixz="-1.17700602431743E-18"
        iyy="0.0524105342655651"
        iyz="-4.08407090334487E-19"
        izz="0.0471742267451067" />
    </inertial>
    <visual>
      <origin
        xyz="0 0 0"
        rpy="0 0 0" />
      <geometry>
        <mesh
          filename="package://optimus_corrected_origin/meshes/FR_inner_wheel_connector_link.STL" />
      </geometry>
      <material
        name="">
        <color
          rgba="0.792156862745098 0.819607843137255 0.933333333333333 1" />
      </material>
    </visual>
    <collision>
      <origin
        xyz="0 0 0"
        rpy="0 0 0" />
      <geometry>
        <mesh
          filename="package://optimus_corrected_origin/meshes/FR_inner_wheel_connector_link.STL" />
      </geometry>
    </collision>
  </link>

  <joint
    name="FR_inner_wheel_connector_joint"
    type="fixed">
    <origin
      xyz="0.15 -0.265 -0.1"
      rpy="0 0 0" />
    <parent
      link="chassis_link" />
    <child
      link="FR_inner_wheel_connector_link" />
    <axis
      xyz="0 0 0" />
  </joint>
  
  <link
    name="FR_inner_wheel_link">
    <inertial>
      <origin
        xyz="-3.31118514906859E-06 0.122556779088169 -5.18267951332696E-07"
        rpy="0 0 0" />
      <mass
        value="5.00504892402194" />
      <inertia
        ixx="0.0924069493556727"
        ixy="2.35690015618929E-07"
        ixz="9.12031624363562E-08"
        iyy="0.144720367920832"
        iyz="3.71035989474246E-08"
        izz="0.0924063846028681" />
    </inertial>
    <visual>
      <origin
        xyz="0 0 0"
        rpy="0 0 0" />
      <geometry>
        <mesh
          filename="package://optimus_corrected_origin/meshes/FR_inner_wheel_link.STL" />
      </geometry>
      <material
        name="">
        <color
          rgba="0.792156862745098 0.819607843137255 0.933333333333333 1" />
      </material>
    </visual>
    <collision>
      <origin
        xyz="0 0 0"
        rpy="0 0 0" />
      <geometry>
        <mesh
          filename="package://optimus_corrected_origin/meshes/FR_inner_wheel_link.STL" />
      </geometry>
    </collision>
  </link>

  <joint
    name="FR_inner_wheel_joint"
    type="continuous">
    <origin
      xyz="0.32 0.025 0"
      rpy="0 0 0" />
    <parent
      link="FR_inner_wheel_connector_link" />
    <child
      link="FR_inner_wheel_link" />
    <axis
      xyz="0 1 0" />
  </joint>
  
  <link
    name="RL_inner_wheel_connector_link">
    <inertial>
      <origin
        xyz="-0.20508770745258 0.000744286749609246 0"
        rpy="0 0 0" />
      <mass
        value="3.16570796326795" />
      <inertia
        ixx="0.00666180087935194"
        ixy="-0.000247607077286711"
        ixz="-8.57886467619125E-18"
        iyy="0.0524105342655653"
        iyz="-2.27692614209372E-18"
        izz="0.0471742267451069" />
    </inertial>
    <visual>
      <origin
        xyz="0 0 0"
        rpy="0 0 0" />
      <geometry>
        <mesh
          filename="package://optimus_corrected_origin/meshes/RL_inner_wheel_connector_link.STL" />
      </geometry>
      <material
        name="">
        <color
          rgba="0.792156862745098 0.819607843137255 0.933333333333333 1" />
      </material>
    </visual>
    <collision>
      <origin
        xyz="0 0 0"
        rpy="0 0 0" />
      <geometry>
        <mesh
          filename="package://optimus_corrected_origin/meshes/RL_inner_wheel_connector_link.STL" />
      </geometry>
    </collision>
  </link>

  <joint
    name="RL_inner_wheel_connector_joint"
    type="fixed">
    <origin
      xyz="-0.15 0.265 -0.1"
      rpy="0 0 0" />
    <parent
      link="chassis_link" />
    <child
      link="RL_inner_wheel_connector_link" />
    <axis
      xyz="0 0 0" />
  </joint>
  
  <link
    name="RL_inner_wheel_link">
    <inertial>
      <origin
        xyz="2.39870415552623E-06 -0.122556778342622 2.34067658932968E-06"
        rpy="0 0 0" />
      <mass
        value="5.00504876897168" />
      <inertia
        ixx="0.0924066747929623"
        ixy="1.70910468737889E-07"
        ixz="2.96635054499153E-07"
        iyy="0.144720367774988"
        iyz="1.66481485161672E-07"
        izz="0.0924066589673187" />
    </inertial>
    <visual>
      <origin
        xyz="0 0 0"
        rpy="0 0 0" />
      <geometry>
        <mesh
          filename="package://optimus_corrected_origin/meshes/RL_inner_wheel_link.STL" />
      </geometry>
      <material
        name="">
        <color
          rgba="0.792156862745098 0.819607843137255 0.933333333333333 1" />
      </material>
    </visual>
    <collision>
      <origin
        xyz="0 0 0"
        rpy="0 0 0" />
      <geometry>
        <mesh
          filename="package://optimus_corrected_origin/meshes/RL_inner_wheel_link.STL" />
      </geometry>
    </collision>
  </link>

  <joint
    name="RL_inner_wheel_joint"
    type="continuous">
    <origin
      xyz="-0.32 -0.025 0"
      rpy="0 0 0" />
    <parent
      link="RL_inner_wheel_connector_link" />
    <child
      link="RL_inner_wheel_link" />
    <axis
      xyz="0 -1 0" />
  </joint>
  
  <link
    name="RR_inner_wheel_connector_link">
    <inertial>
      <origin
        xyz="-0.20508770745258 -0.000744286749609135 1.11022302462516E-16"
        rpy="0 0 0" />
      <mass
        value="3.16570796326795" />
      <inertia
        ixx="0.00666180087935192"
        ixy="0.000247607077286714"
        ixz="3.34428024835884E-18"
        iyy="0.0524105342655651"
        iyz="-2.59900485902853E-19"
        izz="0.0471742267451067" />
    </inertial>
    <visual>
      <origin
        xyz="0 0 0"
        rpy="0 0 0" />
      <geometry>
        <mesh
          filename="package://optimus_corrected_origin/meshes/RR_inner_wheel_connector_link.STL" />
      </geometry>
      <material
        name="">
        <color
          rgba="0.792156862745098 0.819607843137255 0.933333333333333 1" />
      </material>
    </visual>
    <collision>
      <origin
        xyz="0 0 0"
        rpy="0 0 0" />
      <geometry>
        <mesh
          filename="package://optimus_corrected_origin/meshes/RR_inner_wheel_connector_link.STL" />
      </geometry>
    </collision>
  </link>

  <joint
    name="RR_inner_wheel_connector_joint"
    type="fixed">
    <origin
      xyz="-0.15 -0.265 -0.1"
      rpy="0 0 0" />
    <parent
      link="chassis_link" />
    <child
      link="RR_inner_wheel_connector_link" />
    <axis
      xyz="0 0 0" />
  </joint>
  
  <link
    name="RR_inner_wheel_link">
    <inertial>
      <origin
        xyz="1.24620017638577E-07 0.122556779088174 -3.34918177913313E-06"
        rpy="0 0 0" />
      <mass
        value="5.00504892402154" />
      <inertia
        ixx="0.0924063711022311"
        ixy="-9.08227080992973E-09"
        ixz="-2.26104982609489E-08"
        iyy="0.144720367920822"
        iyz="2.38419740676118E-07"
        izz="0.0924069628562967" />
    </inertial>
    <visual>
      <origin
        xyz="0 0 0"
        rpy="0 0 0" />
      <geometry>
        <mesh
          filename="package://optimus_corrected_origin/meshes/RR_inner_wheel_link.STL" />
      </geometry>
      <material
        name="">
        <color
          rgba="0.792156862745098 0.819607843137255 0.933333333333333 1" />
      </material>
    </visual>
    <collision>
      <origin
        xyz="0 0 0"
        rpy="0 0 0" />
      <geometry>
        <mesh
          filename="package://optimus_corrected_origin/meshes/RR_inner_wheel_link.STL" />
      </geometry>
    </collision>
  </link>

  <joint
    name="RR_inner_wheel_joint"
    type="continuous">
    <origin
      xyz="-0.32 0.025 0"
      rpy="0 0 0" />
    <parent
      link="RR_inner_wheel_connector_link" />
    <child
      link="RR_inner_wheel_link" />
    <axis
      xyz="0 1 0" />
  </joint>
</robot>