<?xml version="1.0" encoding="utf-8"?>
<!-- This URDF was automatically created by SolidWorks to URDF Exporter! Originally created by Stephen Brawner (brawner@gmail.com) 
     Commit Version: 1.6.0-1-g15f4949  Build Version: 1.6.7594.29634
     For more information, please see http://wiki.ros.org/sw_urdf_exporter -->
<robot
  name="optimus_front" xmlns:xacro="http://ros.org/wiki/xacro">

  <xacro:include filename="$(find optimus_front)/urdf/optimus_front.gazebo" />

  <link
    name="optimus_front">
    <inertial>
      <origin
        xyz="0.02527 -5.5511E-17 0.44"
        rpy="0 0 0" />
      <mass
        value="122.44" />
      <inertia
        ixx="4.8934"
        ixy="4.7307E-16"
        ixz="7.5918E-17"
        iyy="11.325"
        iyz="-4.8804E-17"
        izz="15.407" />
    </inertial>
    <visual>
      <origin
        xyz="0 0 0"
        rpy="0 0 0" />
      <geometry>
        <mesh
          filename="package://optimus_front/meshes/optimus_front.STL" />
      </geometry>
      <material
        name="">
        <color
          rgba="0.79216 0.81961 0.93333 1" />
      </material>
    </visual>
    <collision>
      <origin
        xyz="0 0 0"
        rpy="0 0 0" />
      <geometry>
        <mesh
          filename="package://optimus_front/meshes/optimus_front.STL" />
      </geometry>
    </collision>
  </link>
  
  <link
    name="FR_outer_wheel_connector_link">
    <inertial>
      <origin
        xyz="0.32228 -0.1 -1.5632E-17"
        rpy="0 0 0" />
      <mass
        value="27.916" />
      <inertia
        ixx="0.19555"
        ixy="-5.5199E-17"
        ixz="1.6328E-16"
        iyy="1.4236"
        iyz="4.1633E-19"
        izz="1.4141" />
    </inertial>
    <visual>
      <origin
        xyz="0 0 0"
        rpy="0 0 0" />
      <geometry>
        <mesh
          filename="package://optimus_front/meshes/FR_outer_wheel_connector_link.STL" />
      </geometry>
      <material
        name="">
        <color
          rgba="0.79216 0.81961 0.93333 1" />
      </material>
    </visual>
    <collision>
      <origin
        xyz="0 0 0"
        rpy="0 0 0" />
      <geometry>
        <mesh
          filename="package://optimus_front/meshes/FR_outer_wheel_connector_link.STL" />
      </geometry>
    </collision>
  </link>
  
  <joint
    name="FR_outer_wheel_connector_joint"
    type="revolute">
    <origin
      xyz="0.4 -0.3 0.44"
      rpy="0 0 0" />
    <parent
      link="optimus_front" />
    <child
      link="FR_outer_wheel_connector_link" />
    <axis
      xyz="0 1 0" />
    <limit
      lower="1.57"
      upper="0"
      effort="10"
      velocity="10" />
  </joint>

  <transmission name="FR_outer_wheel_connector_trans">
    <type>transmission_interface/SimpleTransmission</type>
    <joint name="FR_outer_wheel_connector_joint">
      <hardwareInterface>hardware_interface/PositionJointInterface</hardwareInterface>
    </joint>
    <actuator name="FR_outer_wheel_connector_actuator">
      <mechanicalReduction>1</mechanicalReduction>
      <hardwareInterface>hardware_interface/PositionJointInterface</hardwareInterface>
    </actuator>
  </transmission>
  
  <link
    name="FR_outer_wheel_link">
    <inertial>
      <origin
        xyz="-3.1136E-06 -0.51235 -8.1188E-07"
        rpy="0 0 0" />
      <mass
        value="41.762" />
      <inertia
        ixx="2.9874"
        ixy="-7.3894E-06"
        ixz="4.6203E-06"
        iyy="4.6324"
        iyz="-1.9206E-06"
        izz="2.9874" />
    </inertial>
    <visual>
      <origin
        xyz="0 0 0"
        rpy="0 0 0" />
      <geometry>
        <mesh
          filename="package://optimus_front/meshes/FR_outer_wheel_link.STL" />
      </geometry>
      <material
        name="">
        <color
          rgba="0.79216 0.81961 0.93333 1" />
      </material>
    </visual>
    <collision>
      <origin
        xyz="0 0 0"
        rpy="0 0 0" />
      <geometry>
        <mesh
          filename="package://optimus_front/meshes/FR_outer_wheel_link.STL" />
      </geometry>
    </collision>
  </link>
  
  <joint
    name="FR_outer_wheel_joint"
    type="continuous">
    <origin
      xyz="0.6 0 0"
      rpy="0 0 0" />
    <parent
      link="FR_outer_wheel_connector_link" />
    <child
      link="FR_outer_wheel_link" />
    <axis
      xyz="0 1 0" />
  </joint>

  <transmission name="FR_outer_wheel_trans">
    <type>transmission_interface/SimpleTransmission</type>
    <joint name="FR_outer_wheel_joint">
      <hardwareInterface>hardware_interface/VelocityJointInterface</hardwareInterface>
    </joint>
    <actuator name="FR_outer_wheel_actuator">
      <mechanicalReduction>1</mechanicalReduction>
      <hardwareInterface>hardware_interface/VelocityJointInterface</hardwareInterface>
    </actuator>
  </transmission>
  
  <link
    name="FL_outer_wheel_connector_link">
    <inertial>
      <origin
        xyz="0.32228 0.1 -4.4016E-17"
        rpy="0 0 0" />
      <mass
        value="27.916" />
      <inertia
        ixx="0.19555"
        ixy="-2.088E-17"
        ixz="7.16E-17"
        iyy="1.4236"
        iyz="2.0447E-17"
        izz="1.4141" />
    </inertial>
    <visual>
      <origin
        xyz="0 0 0"
        rpy="0 0 0" />
      <geometry>
        <mesh
          filename="package://optimus_front/meshes/FL_outer_wheel_connector_link.STL" />
      </geometry>
      <material
        name="">
        <color
          rgba="0.79216 0.81961 0.93333 1" />
      </material>
    </visual>
    <collision>
      <origin
        xyz="0 0 0"
        rpy="0 0 0" />
      <geometry>
        <mesh
          filename="package://optimus_front/meshes/FL_outer_wheel_connector_link.STL" />
      </geometry>
    </collision>
  </link>
  
  <joint
    name="FL_outer_wheel_connector_joint"
    type="revolute">
    <origin
      xyz="0.4 0.3 0.44"
      rpy="0 0 0" />
    <parent
      link="optimus_front" />
    <child
      link="FL_outer_wheel_connector_link" />
    <axis
      xyz="0 1 0" />
    <limit
      lower="0"
      upper="0"
      effort="10"
      velocity="10" />
  </joint>

  <transmission name="FL_outer_wheel_connector_trans">
    <type>transmission_interface/SimpleTransmission</type>
    <joint name="FL_outer_wheel_connector_joint">
      <hardwareInterface>hardware_interface/PositionJointInterface</hardwareInterface>
    </joint>
    <actuator name="FL_outer_wheel_connector_actuator">
      <mechanicalReduction>1</mechanicalReduction>
      <hardwareInterface>hardware_interface/PositionJointInterface</hardwareInterface>
    </actuator>
  </transmission>
  
  <link
    name="FL_outer_wheel_link">
    <inertial>
      <origin
        xyz="-1.331E-06 0.51235 -2.9296E-06"
        rpy="0 0 0" />
      <mass
        value="41.762" />
      <inertia
        ixx="2.9874"
        ixy="3.1528E-06"
        ixz="7.1398E-06"
        iyy="4.6324"
        iyz="6.9536E-06"
        izz="2.9874" />
    </inertial>
    <visual>
      <origin
        xyz="0 0 0"
        rpy="0 0 0" />
      <geometry>
        <mesh
          filename="package://optimus_front/meshes/FL_outer_wheel_link.STL" />
      </geometry>
      <material
        name="">
        <color
          rgba="0.79216 0.81961 0.93333 1" />
      </material>
    </visual>
    <collision>
      <origin
        xyz="0 0 0"
        rpy="0 0 0" />
      <geometry>
        <mesh
          filename="package://optimus_front/meshes/FL_outer_wheel_link.STL" />
      </geometry>
    </collision>
  </link>
  
  <joint
    name="FL_outer_wheel_joint"
    type="continuous">
    <origin
      xyz="0.6 0 0"
      rpy="0 0 0" />
    <parent
      link="FL_outer_wheel_connector_link" />
    <child
      link="FL_outer_wheel_link" />
    <axis
      xyz="0 1 0" />
  </joint>

  <transmission name="FL_outer_wheel_trans">
    <type>transmission_interface/SimpleTransmission</type>
    <joint name="FL_outer_wheel_joint">
      <hardwareInterface>hardware_interface/VelocityJointInterface</hardwareInterface>
    </joint>
    <actuator name="FL_outer_wheel_actuator">
      <mechanicalReduction>1</mechanicalReduction>
      <hardwareInterface>hardware_interface/VelocityJointInterface</hardwareInterface>
    </actuator>
  </transmission>
  
  <link
    name="FR_inner_wheel_connector_link">
    <inertial>
      <origin
        xyz="0.12462 -0.034175 -4.7957E-18"
        rpy="0 0 0" />
      <mass
        value="2.8575" />
      <inertia
        ixx="0.0058124"
        ixy="0.00029364"
        ixz="-6.7493E-20"
        iyy="0.040326"
        iyz="-1.441E-19"
        izz="0.035811" />
    </inertial>
    <visual>
      <origin
        xyz="0 0 0"
        rpy="0 0 0" />
      <geometry>
        <mesh
          filename="package://optimus_front/meshes/FR_inner_wheel_connector_link.STL" />
      </geometry>
      <material
        name="">
        <color
          rgba="0.79216 0.81961 0.93333 1" />
      </material>
    </visual>
    <collision>
      <origin
        xyz="0 0 0"
        rpy="0 0 0" />
      <geometry>
        <mesh
          filename="package://optimus_front/meshes/FR_inner_wheel_connector_link.STL" />
      </geometry>
    </collision>
  </link>
  
  <joint
    name="FR_inner_wheel_connector_joint"
    type="revolute">
    <origin
      xyz="-0.25 -0.3 0.44"
      rpy="0 0 0" />
    <parent
      link="optimus_front" />
    <child
      link="FR_inner_wheel_connector_link" />
    <axis
      xyz="0 1 0" />
    <limit
      lower="0"
      upper="0"
      effort="10"
      velocity="10" />
  </joint>

  <transmission name="FR_inner_wheel_connector_trans">
    <type>transmission_interface/SimpleTransmission</type>
    <joint name="FR_inner_wheel_connector_joint">
      <hardwareInterface>hardware_interface/PositionJointInterface</hardwareInterface>
    </joint>
    <actuator name="FR_inner_wheel_connector_actuator">
      <mechanicalReduction>1</mechanicalReduction>
      <hardwareInterface>hardware_interface/PositionJointInterface</hardwareInterface>
    </actuator>
  </transmission>
  
  <link
    name="FR_inner_wheel_link">
    <inertial>
      <origin
        xyz="2.038E-06 -0.12256 -2.6606E-06"
        rpy="0 0 0" />
      <mass
        value="5.005" />
      <inertia
        ixx="0.092407"
        ixy="1.4492E-07"
        ixz="-2.8633E-07"
        iyy="0.14472"
        iyz="-1.8954E-07"
        izz="0.092407" />
    </inertial>
    <visual>
      <origin
        xyz="0 0 0"
        rpy="0 0 0" />
      <geometry>
        <mesh
          filename="package://optimus_front/meshes/FR_inner_wheel_link.STL" />
      </geometry>
      <material
        name="">
        <color
          rgba="0.79216 0.81961 0.93333 1" />
      </material>
    </visual>
    <collision>
      <origin
        xyz="0 0 0"
        rpy="0 0 0" />
      <geometry>
        <mesh
          filename="package://optimus_front/meshes/FR_inner_wheel_link.STL" />
      </geometry>
    </collision>
  </link>
  
  <joint
    name="FR_inner_wheel_joint"
    type="continuous">
    <origin
      xyz="0.22 -0.06 0"
      rpy="0 0 0" />
    <parent
      link="FR_inner_wheel_connector_link" />
    <child
      link="FR_inner_wheel_link" />
    <axis
      xyz="0 1 0" />
  </joint>

  <transmission name="FR_inner_wheel_trans">
    <type>transmission_interface/SimpleTransmission</type>
    <joint name="FR_inner_wheel_joint">
      <hardwareInterface>hardware_interface/VelocityJointInterface</hardwareInterface>
    </joint>
    <actuator name="FR_inner_wheel_actuator">
      <mechanicalReduction>1</mechanicalReduction>
      <hardwareInterface>hardware_interface/VelocityJointInterface</hardwareInterface>
    </actuator>
  </transmission>
  
  <link
    name="FL_inner_wheel_connector_link">
    <inertial>
      <origin
        xyz="0.12462 0.034175 -5.101E-17"
        rpy="0 0 0" />
      <mass
        value="2.8575" />
      <inertia
        ixx="0.0058124"
        ixy="-0.00029364"
        ixz="-8.4277E-19"
        iyy="0.040326"
        iyz="1.5116E-19"
        izz="0.035811" />
    </inertial>
    <visual>
      <origin
        xyz="0 0 0"
        rpy="0 0 0" />
      <geometry>
        <mesh
          filename="package://optimus_front/meshes/FL_inner_wheel_connector_link.STL" />
      </geometry>
      <material
        name="">
        <color
          rgba="0.79216 0.81961 0.93333 1" />
      </material>
    </visual>
    <collision>
      <origin
        xyz="0 0 0"
        rpy="0 0 0" />
      <geometry>
        <mesh
          filename="package://optimus_front/meshes/FL_inner_wheel_connector_link.STL" />
      </geometry>
    </collision>
  </link>
  
  <joint
    name="FL_inner_wheel_connector_joint"
    type="revolute">
    <origin
      xyz="-0.25 0.3 0.44"
      rpy="0 0 0" />
    <parent
      link="optimus_front" />
    <child
      link="FL_inner_wheel_connector_link" />
    <axis
      xyz="0 1 0" />
    <limit
      lower="0"
      upper="0"
      effort="10"
      velocity="10" />
  </joint>

  <transmission name="FL_inner_wheel_connector_trans">
    <type>transmission_interface/SimpleTransmission</type>
    <joint name="FL_inner_wheel_connector_joint">
      <hardwareInterface>hardware_interface/PositionJointInterface</hardwareInterface>
    </joint>
    <actuator name="FL_inner_wheel_connector_actuator">
      <mechanicalReduction>1</mechanicalReduction>
      <hardwareInterface>hardware_interface/PositionJointInterface</hardwareInterface>
    </actuator>
  </transmission>
  
  <link
    name="FL_inner_wheel_link">
    <inertial>
      <origin
        xyz="2.3339E-06 0.12256 2.4053E-06"
        rpy="0 0 0" />
      <mass
        value="5.005" />
      <inertia
        ixx="0.092407"
        ixy="-1.66E-07"
        ixz="2.9659E-07"
        iyy="0.14472"
        iyz="-1.7138E-07"
        izz="0.092407" />
    </inertial>
    <visual>
      <origin
        xyz="0 0 0"
        rpy="0 0 0" />
      <geometry>
        <mesh
          filename="package://optimus_front/meshes/FL_inner_wheel_link.STL" />
      </geometry>
      <material
        name="">
        <color
          rgba="0.79216 0.81961 0.93333 1" />
      </material>
    </visual>
    <collision>
      <origin
        xyz="0 0 0"
        rpy="0 0 0" />
      <geometry>
        <mesh
          filename="package://optimus_front/meshes/FL_inner_wheel_link.STL" />
      </geometry>
    </collision>
  </link>
  
  <joint
    name="FL_inner_wheel_joint"
    type="continuous">
    <origin
      xyz="0.22 0.06 0"
      rpy="0 0 0" />
    <parent
      link="FL_inner_wheel_connector_link" />
    <child
      link="FL_inner_wheel_link" />
    <axis
      xyz="0 1 0" />
  </joint>

  <transmission name="FL_inner_wheel_trans">
    <type>transmission_interface/SimpleTransmission</type>
    <joint name="FL_inner_wheel_joint">
      <hardwareInterface>hardware_interface/VelocityJointInterface</hardwareInterface>
    </joint>
    <actuator name="FL_inner_wheel_actuator">
      <mechanicalReduction>1</mechanicalReduction>
      <hardwareInterface>hardware_interface/VelocityJointInterface</hardwareInterface>
    </actuator>
  </transmission>
  
  <link
    name="docker_link">
    <inertial>
      <origin
        xyz="0.0045718 -5.5511E-17 -0.1"
        rpy="0 0 0" />
      <mass
        value="21.989" />
      <inertia
        ixx="0.74725"
        ixy="-2.5019E-17"
        ixz="1.0257E-17"
        iyy="0.14701"
        iyz="-3.4694E-17"
        izz="0.74767" />
    </inertial>
    <visual>
      <origin
        xyz="0 0 0"
        rpy="0 0 0" />
      <geometry>
        <mesh
          filename="package://optimus_front/meshes/docker_link.STL" />
      </geometry>
      <material
        name="">
        <color
          rgba="0.79216 0.81961 0.93333 1" />
      </material>
    </visual>
    <collision>
      <origin
        xyz="0 0 0"
        rpy="0 0 0" />
      <geometry>
        <mesh
          filename="package://optimus_front/meshes/docker_link.STL" />
      </geometry>
    </collision>
  </link>
  
  <joint
    name="docker_joint"
    type="fixed">
    <origin
      xyz="-0.5 0 0.74"
      rpy="0 0 0" />
    <parent
      link="optimus_front" />
    <child
      link="docker_link" />
    <axis
      xyz="0 0 0" />
  </joint>
  
  <link
    name="R_docker_shaft_link">
    <inertial>
      <origin
        xyz="0 0 -0.1"
        rpy="0 0 0" />
      <mass
        value="1.0053" />
      <inertia
        ixx="0.0037532"
        ixy="-4.6587E-20"
        ixz="-4.5175E-20"
        iyy="0.0037532"
        iyz="5.9411E-36"
        izz="0.00080425" />
    </inertial>
    <visual>
      <origin
        xyz="0 0 0"
        rpy="0 0 0" />
      <geometry>
        <mesh
          filename="package://optimus_front/meshes/R_docker_shaft_link.STL" />
      </geometry>
      <material
        name="">
        <color
          rgba="0.79216 0.81961 0.93333 1" />
      </material>
    </visual>
    <collision>
      <origin
        xyz="0 0 0"
        rpy="0 0 0" />
      <geometry>
        <mesh
          filename="package://optimus_front/meshes/R_docker_shaft_link.STL" />
      </geometry>
    </collision>
  </link>
  
  <joint
    name="R_docker_shaft_joint"
    type="prismatic">
    <origin
      xyz="-0.05 -0.15 0"
      rpy="0 0 0" />
    <parent
      link="docker_link" />
    <child
      link="R_docker_shaft_link" />
    <axis
      xyz="0 0 1" />
    <limit
      lower="-0.2"
      upper="0"
      effort="10"
      velocity="10" />
  </joint>
  
  <link
    name="L_docker_shaft_link">
    <inertial>
      <origin
        xyz="0 -1.1102E-16 -0.1"
        rpy="0 0 0" />
      <mass
        value="1.0053" />
      <inertia
        ixx="0.0037532"
        ixy="-1.0588E-21"
        ixz="4.3507E-36"
        iyy="0.0037532"
        iyz="1.177E-35"
        izz="0.00080425" />
    </inertial>
    <visual>
      <origin
        xyz="0 0 0"
        rpy="0 0 0" />
      <geometry>
        <mesh
          filename="package://optimus_front/meshes/L_docker_shaft_link.STL" />
      </geometry>
      <material
        name="">
        <color
          rgba="0.79216 0.81961 0.93333 1" />
      </material>
    </visual>
    <collision>
      <origin
        xyz="0 0 0"
        rpy="0 0 0" />
      <geometry>
        <mesh
          filename="package://optimus_front/meshes/L_docker_shaft_link.STL" />
      </geometry>
    </collision>
  </link>
  
  <joint
    name="L_docker_shaft_joint"
    type="prismatic">
    <origin
      xyz="-0.05 0.15 0"
      rpy="0 0 0" />
    <parent
      link="docker_link" />
    <child
      link="L_docker_shaft_link" />
    <axis
      xyz="0 0 1" />
    <limit
      lower="-0.2"
      upper="0"
      effort="10"
      velocity="10" />
  </joint>
</robot>